Workbook

Sheet HVAC Price List
A1: TradeOS — HVAC Supply Price List | Johnstone Supply | Demo Data
A2: Prices effective: Jan 2025 | Demo only — not real supplier pricing | Update with actual Johnstone pricing before pilot
A3: SKU | B3: Description | C3: Category | D3: Unit | E3: Unit Cost | F3: Markup % | G3: Customer Price
A4: ── CONDENSERS & SPLIT SYSTEMS ──
A5: HVAC-CAR-CA16-024 | B5: Carrier CA16NA024 — 2-ton 16 SEER Condenser | C5: Condensers | D5: ea | E5: 980 | F5: 0.3 | G5: =E5*(1+F5) -> 1274
A6: HVAC-CAR-CA16-036 | B6: Carrier CA16NA036 — 3-ton 16 SEER Condenser | C6: Condensers | D6: ea | E6: 1240 | F6: 0.3 | G6: =E6*(1+F6) -> 1612
A7: HVAC-CAR-CA16-048 | B7: Carrier CA16NA048 — 4-ton 16 SEER Condenser | C7: Condensers | D7: ea | E7: 1520 | F7: 0.3 | G7: =E7*(1+F7) -> 1976
A8: HVAC-GDM-GSX14-024 | B8: Goodman GSX14-024 — 2-ton 14 SEER Condenser | C8: Condensers | D8: ea | E8: 740 | F8: 0.3 | G8: =E8*(1+F8) -> 962
A9: HVAC-GDM-GSX14-036 | B9: Goodman GSX14-036 — 3-ton 14 SEER Condenser | C9: Condensers | D9: ea | E9: 920 | F9: 0.3 | G9: =E9*(1+F9) -> 1196
A10: HVAC-LEN-XC16-036 | B10: Lennox XC16-036 — 3-ton 16 SEER Condenser | C10: Condensers | D10: ea | E10: 1380 | F10: 0.3 | G10: =E10*(1+F10) -> 1794
A11: ── AIR HANDLERS & COILS ──
A12: HVAC-CAR-FV4C-024 | B12: Carrier FV4CNF002 — 2-ton Air Handler | C12: Air Handlers | D12: ea | E12: 620 | F12: 0.3 | G12: =E12*(1+F12) -> 806
A13: HVAC-CAR-FV4C-036 | B13: Carrier FV4CNF003 — 3-ton Air Handler | C13: Air Handlers | D13: ea | E13: 740 | F13: 0.3 | G13: =E13*(1+F13) -> 962
A14: HVAC-GDM-ARUF-036 | B14: Goodman ARUF36C14 — 3-ton Air Handler | C14: Air Handlers | D14: ea | E14: 560 | F14: 0.3 | G14: =E14*(1+F14) -> 728
A15: ── REFRIGERANT ──
A16: HVAC-REF-R410A-25 | B16: R-410A Refrigerant — 25 lb cylinder | C16: Refrigerant | D16: cyl | E16: 148 | F16: 0.3 | G16: =E16*(1+F16) -> 192.4
A17: HVAC-REF-R410A-LB | B17: R-410A — per pound (field charge) | C17: Refrigerant | D17: lb | E17: 6.2 | F17: 0.3 | G17: =E17*(1+F17) -> 8.06
A18: HVAC-REF-R22-REC | B18: R-22 Recovery Cylinder — 30 lb (empty) | C18: Refrigerant | D18: ea | E18: 45 | F18: 0.3 | G18: =E18*(1+F18) -> 58.5
A19: HVAC-REF-R454B-25 | B19: R-454B Refrigerant — 25 lb cylinder (R-22 replacement) | C19: Refrigerant | D19: cyl | E19: 185 | F19: 0.3 | G19: =E19*(1+F19) -> 240.5
A20: ── LINE SETS & FITTINGS ──
A21: HVAC-LS-3878-25 | B21: Line Set 3/8" x 7/8" x 25 ft — pre-charged | C21: Line Sets | D21: set | E21: 88 | F21: 0.3 | G21: =E21*(1+F21) -> 114.4
A22: HVAC-LS-3878-50 | B22: Line Set 3/8" x 7/8" x 50 ft — pre-charged | C22: Line Sets | D22: set | E22: 148 | F22: 0.3 | G22: =E22*(1+F22) -> 192.4
A23: HVAC-LS-INS-78 | B23: Line Set Insulation 7/8" (per ft) | C23: Line Sets | D23: ft | E23: 0.85 | F23: 0.3 | G23: =E23*(1+F23) -> 1.105
A24: HVAC-LS-INS-38 | B24: Line Set Insulation 3/8" (per ft) | C24: Line Sets | D24: ft | E24: 0.55 | F24: 0.3 | G24: =E24*(1+F24) -> 0.715
A25: HVAC-LS-FLUSH | B25: Line Set Flush Kit — nitrogen + fittings | C25: Line Sets | D25: kit | E25: 38 | F25: 0.3 | G25: =E25*(1+F25) -> 49.4
A26: HVAC-FIT-FLARE | B26: Flare Fitting Set — 1/4" to 7/8" assorted | C26: Fittings | D26: set | E26: 22 | F26: 0.3 | G26: =E26*(1+F26) -> 28.6
A27: HVAC-FIT-N2 | B27: Nitrogen — purge/pressure test cylinder | C27: Fittings | D27: ea | E27: 28 | F27: 0.3 | G27: =E27*(1+F27) -> 36.4
A28: ── ELECTRICAL & DISCONNECT ──
A29: HVAC-EL-DISC-60F | B29: Disconnect Box — 60A fusible | C29: Electrical | D29: ea | E29: 34 | F29: 0.3 | G29: =E29*(1+F29) -> 44.2
A30: HVAC-EL-DISC-60NF | B30: Disconnect Box — 60A non-fusible | C30: Electrical | D30: ea | E30: 24 | F30: 0.3 | G30: =E30*(1+F30) -> 31.2
A31: HVAC-EL-FUSE-40 | B31: Fuses — 40A time-delay (pair) | C31: Electrical | D31: pr | E31: 8.5 | F31: 0.3 | G31: =E31*(1+F31) -> 11.05
A32: HVAC-EL-FUSE-30 | B32: Fuses — 30A time-delay (pair) | C32: Electrical | D32: pr | E32: 6.5 | F32: 0.3 | G32: =E32*(1+F32) -> 8.45
A33: HVAC-EL-WIRE-10 | B33: 10/2 NM-B Wire w/ Ground (per ft) | C33: Electrical | D33: ft | E33: 0.58 | F33: 0.3 | G33: =E33*(1+F33) -> 0.754
A34: HVAC-EL-WIRE-10R | B34: 10/2 NM-B Wire — 50 ft roll | C34: Electrical | D34: roll | E34: 32 | F34: 0.3 | G34: =E34*(1+F34) -> 41.6
A35: ── CAPACITORS & COMPONENTS ──
A36: HVAC-CAP-45-5 | B36: Run Capacitor — 45/5 MFD 370V Dual (most common) | C36: Capacitors | D36: ea | E36: 14.5 | F36: 0.3 | G36: =E36*(1+F36) -> 18.85
A37: HVAC-CAP-35-5 | B37: Run Capacitor — 35/5 MFD 370V Dual | C37: Capacitors | D37: ea | E37: 12 | F37: 0.3 | G37: =E37*(1+F37) -> 15.6
A38: HVAC-CAP-55-5 | B38: Run Capacitor — 55/5 MFD 370V Dual | C38: Capacitors | D38: ea | E38: 16 | F38: 0.3 | G38: =E38*(1+F38) -> 20.8
A39: HVAC-CAP-7-5 | B39: Run Capacitor — 7.5 MFD 370V Single (fan motor) | C39: Capacitors | D39: ea | E39: 8.5 | F39: 0.3 | G39: =E39*(1+F39) -> 11.05
A40: HVAC-CAP-5 | B40: Run Capacitor — 5 MFD 370V Single | C40: Capacitors | D40: ea | E40: 7.5 | F40: 0.3 | G40: =E40*(1+F40) -> 9.75
...

Sheet Job Templates
A1: TradeOS — HVAC Job Templates | Reference for AI Supply List Generation
A2: These templates seed the AI supply list. AI adds job-specific items on top. Tech confirms before order is placed.
A3: Job Type | B3: SKU | C3: Default Qty | D3: Unit | E3: Est. Cost | F3: Notes
A4: ── CONDENSER REPLACEMENT — 3-TON R-410A ──
A5: Condenser Replace | B5: HVAC-CAR-CA16-036 | C5: 1 | D5: ea | E5: =IFERROR(VLOOKUP(B5,'HVAC Price List'!$A:$E,5,0)*C5,"—") -> 1240 | F5: Primary unit — adjust SKU to match job
A6: Condenser Replace | B6: HVAC-REF-R410A-25 | C6: 1 | D6: cyl | E6: =IFERROR(VLOOKUP(B6,'HVAC Price List'!$A:$E,5,0)*C6,"—") -> 148 | F6: Full cylinder standard on replacement
A7: Condenser Replace | B7: HVAC-REF-R22-REC | C7: 1 | D7: ea | E7: =IFERROR(VLOOKUP(B7,'HVAC Price List'!$A:$E,5,0)*C7,"—") -> 45 | F7: R-22 recovery — always on R-22 units
A8: Condenser Replace | B8: HVAC-LS-FLUSH | C8: 1 | D8: kit | E8: =IFERROR(VLOOKUP(B8,'HVAC Price List'!$A:$E,5,0)*C8,"—") -> 38 | F8: Line set flush — R-22 to R-410A transition
A9: Condenser Replace | B9: HVAC-EL-DISC-60F | C9: 1 | D9: ea | E9: =IFERROR(VLOOKUP(B9,'HVAC Price List'!$A:$E,5,0)*C9,"—") -> 34 | F9: Inspect existing — replace if corroded
A10: Condenser Replace | B10: HVAC-EL-FUSE-40 | C10: 1 | D10: pr | E10: =IFERROR(VLOOKUP(B10,'HVAC Price List'!$A:$E,5,0)*C10,"—") -> 8.5 | F10: Match new unit MCA
A11: Condenser Replace | B11: HVAC-FDRIER | C11: 1 | D11: ea | E11: =IFERROR(VLOOKUP(B11,'HVAC Price List'!$A:$E,5,0)*C11,"—") -> 18.5 | F11: Always replace on refrigerant system work
A12: Condenser Replace | B12: HVAC-PAD-SHIM | C12: 1 | D12: set | E12: =IFERROR(VLOOKUP(B12,'HVAC Price List'!$A:$E,5,0)*C12,"—") -> 8.5 | F12: Inspect and level existing pad
A13: Condenser Replace | B13: HVAC-VIBPAD | C13: 1 | D13: ea | E13: =IFERROR(VLOOKUP(B13,'HVAC Price List'!$A:$E,5,0)*C13,"—") -> 18 | F13: Install on new unit
A14: Condenser Replace | B14: HVAC-CON-FOIL | C14: 1 | D14: ea | E14: =IFERROR(VLOOKUP(B14,'HVAC Price List'!$A:$E,5,0)*C14,"—") -> 8.5 | F14: Line set weatherproofing
A15: Condenser Replace | B15: HVAC-CON-ZIP | C15: 1 | D15: pk | E15: =IFERROR(VLOOKUP(B15,'HVAC Price List'!$A:$E,5,0)*C15,"—") -> 6.5 | F15: Line set management
A16: Condenser Replace | B16: HVAC-CON-LEAK | C16: 1 | D16: ea | E16: =IFERROR(VLOOKUP(B16,'HVAC Price List'!$A:$E,5,0)*C16,"—") -> 12 | F16: Post-charge leak check — always
A17: Condenser Replace | B17: HVAC-FIT-N2 | C17: 1 | D17: ea | E17: =IFERROR(VLOOKUP(B17,'HVAC Price List'!$A:$E,5,0)*C17,"—") -> 28 | F17: Pressure test before charge
A18: ── CAPACITOR REPLACEMENT ──
A19: Capacitor Replace | B19: HVAC-CAP-45-5 | C19: 1 | D19: ea | E19: =IFERROR(VLOOKUP(B19,'HVAC Price List'!$A:$E,5,0)*C19,"—") -> 14.5 | F19: Confirm MFD reading before ordering
A20: Capacitor Replace | B20: HVAC-CON-LEAK | C20: 1 | D20: ea | E20: =IFERROR(VLOOKUP(B20,'HVAC Price List'!$A:$E,5,0)*C20,"—") -> 12 | F20: Check refrigerant while in system
A21: ── THERMOSTAT REPLACEMENT ──
A22: Thermostat Replace | B22: HVAC-TSTAT-SMART | C22: 1 | D22: ea | E22: =IFERROR(VLOOKUP(B22,'HVAC Price List'!$A:$E,5,0)*C22,"—") -> 95 | F22: Default to smart — upsell from basic
A23: Thermostat Replace | B23: HVAC-CTRL-WIRE50 | C23: 1 | D23: roll | E23: =IFERROR(VLOOKUP(B23,'HVAC Price List'!$A:$E,5,0)*C23,"—") -> 18 | F23: Run new wire if existing is degraded
A24: ── SERVICE CALL — NO COOL (DIAGNOSTIC) ──
A25: No-Cool Service | B25: HVAC-CAP-45-5 | C25: 1 | D25: ea | E25: =IFERROR(VLOOKUP(B25,'HVAC Price List'!$A:$E,5,0)*C25,"—") -> 14.5 | F25: Most common no-cool cause — carry always
A26: No-Cool Service | B26: HVAC-CONT-2P | C26: 1 | D26: ea | E26: =IFERROR(VLOOKUP(B26,'HVAC Price List'!$A:$E,5,0)*C26,"—") -> 18 | F26: Second most common — carry always
A27: No-Cool Service | B27: HVAC-CON-LEAK | C27: 1 | D27: ea | E27: =IFERROR(VLOOKUP(B27,'HVAC Price List'!$A:$E,5,0)*C27,"—") -> 12 | F27: Check refrigerant charge
A28: No-Cool Service | B28: HVAC-REF-R410A-LB | C28: 2 | D28: lb | E28: =IFERROR(VLOOKUP(B28,'HVAC Price List'!$A:$E,5,0)*C28,"—") -> 12.4 | F28: Top-off if low — note leak source

Sheet Calloway Demo Order
A1: TradeOS — Purchase Order | Calloway Residence | PO #TOS-2024-0847
A2: Customer: | B2: Calloway Residence — 2847 Ridgewood Ct
A3: Job: | B3: Goodman CK36-1A condenser replacement — R-22 to R-410A upgrade
A4: Supplier: | B4: Johnstone Supply — 4821 Industrial Blvd
A5: PO Date: | B5: Tuesday June 17, 2024 — 7:51 PM
A6: Pickup: | B6: Thursday June 19, 2024 — 7:30 AM
A7: Requested by: | B7: Jamie (Owner) — TradeOS PO auto-generated
A9: SKU | B9: Description | C9: Qty | D9: Unit | E9: Unit Cost | F9: Total | G9: Status
A10: HVAC-CAR-CA16-036 | B10: Carrier CA16NA036 — 3-ton 16 SEER Condenser | C10: 1 | D10: ea | E10: 1240 | F10: =C10*E10 -> 1240 | G10: ✅ In stock
A11: HVAC-REF-R410A-25 | B11: R-410A Refrigerant — 25 lb cylinder | C11: 1 | D11: cyl | E11: 148 | F11: =C11*E11 -> 148 | G11: ✅ In stock
A12: HVAC-REF-R22-REC | B12: R-22 Recovery Cylinder — 30 lb | C12: 1 | D12: ea | E12: 45 | F12: =C12*E12 -> 45 | G12: ✅ In stock
A13: HVAC-LS-FLUSH | B13: Line Set Flush Kit — nitrogen + fittings | C13: 1 | D13: kit | E13: 38 | F13: =C13*E13 -> 38 | G13: ✅ In stock
A14: HVAC-EL-DISC-60F | B14: Disconnect Box — 60A fusible | C14: 1 | D14: ea | E14: 34 | F14: =C14*E14 -> 34 | G14: ⚠️ Substituted — see note
A15: HVAC-EL-FUSE-40 | B15: Fuses — 40A time-delay (pair) | C15: 1 | D15: pr | E15: 8.5 | F15: =C15*E15 -> 8.5 | G15: ✅ In stock
A16: HVAC-LS-INS-78 | B16: Line Set Insulation 7/8" (per ft) | C16: 10 | D16: ft | E16: 0.85 | F16: =C16*E16 -> 8.5 | G16: ✅ In stock
A17: HVAC-VIBPAD | B17: Anti-vibration Pad — 24x24 | C17: 1 | D17: ea | E17: 18 | F17: =C17*E17 -> 18 | G17: ✅ In stock
A18: HVAC-FDRIER | B18: Filter Drier — 3/8" sweat | C18: 1 | D18: ea | E18: 18.5 | F18: =C18*E18 -> 18.5 | G18: ✅ In stock
A19: HVAC-CON-LEAK | B19: Refrigerant Leak Detector Fluid | C19: 1 | D19: ea | E19: 12 | F19: =C19*E19 -> 12 | G19: ✅ In stock
A20: HVAC-CON-FOIL | B20: Foil Tape — 2" x 50 ft | C20: 1 | D20: ea | E20: 8.5 | F20: =C20*E20 -> 8.5 | G20: ✅ In stock
A21: HVAC-CON-ZIP | B21: UV-rated Zip Ties — 100-pk | C21: 1 | D21: pk | E21: 6.5 | F21: =C21*E21 -> 6.5 | G21: ✅ In stock
A22: TOTAL MATERIAL COST — Jamie's cost (not shown to customer) | F22: =SUM(F10:F21) -> 1585.5 | G22: Order confirmed 7:54 PM
A24: ⚠️ Substitution note: Eaton DPU222RP (60A disconnect) out of stock. Square D QO230L200PG substituted — same specs, same price. Approved by Jamie 7:54 PM.
